<?xml version="1.0"?>
<sdf version="1.9">
    <world name="SonglingEnvironment">
        <phsyice name="1ms" type="ignored">
            <maxstep_size>0.001</maxstep_size>
            <real_time_factor>1.0</real_time_factor>
        </phsyice>
    <plugin filename="ignition-gazebo-physics-system" name="ignition::gazebo::systems::Physics"></plugin>
    <plugin filename="ignition-gazebo-user-commands-system" name="ignition::gazebo::systems::UserCommands"></plugin>
    <plugin filename="ignition-gazebo-scene-broadcaster-system" name="ignition::gazebo::systems::SceneBroadcaster"></plugin>
    <plugin filename="ignition-gazebo-imu-system" name="ignition::gazebo::systems::Imu"></plugin>
    <plugin filename="ignition-gazebo-sensors-system" name="ignition::gazebo::systems::Sensors">
        <render_engine>ogre2</render_engine>
    </plugin>
    <gui fullscreen="0">
        <plugin filename="GzScene3D" name="3D View">
            <ignition-gui>
                <title>3D View</title>
                <property type="bool" key="showTitleBar">false</property>
                <property type="string" key="state">docked</property>
            </ignition-gui>
            
            <engine>ogre</engine>
            <scene>scene</scene>
            <ambient_light>0.4 0.4 0.4</ambient_light>
            <background_color>0.8 0.8 0.8</background_color>
        </plugin>
        <plugin filename="WorldControl" name="World control">
            <ignition-gui>
                <title>World control</title>
                <property type="bool" key="showTitleBar">false</property>
                <property type="bool" key="resizable">false</property>
                <property type="double" key="height">72</property>
                <property type="double" key="width">121</property>
                <property type="double" key="z">1</property>
                <property type="string" key="state">floating</property>
                <anchors target="3D View">
                    <line own="left" target="left" />
                    <line own="bottom" target="bottom" />
                </anchors>
            </ignition-gui>
            <play_pause>true</play_pause>
            <step>true</step>
            <start_paused>true</start_paused>
            <service>/world/SonglingEnvironment/control</service>
            <stats_topic>/world/SonglingEnvironment/stats</stats_topic>
        </plugin>

            <plugin filename="WorldStats" name="World stats">
            <ignition-gui>
                <title>World stats</title>
                <property type="bool" key="showTitleBar">false</property>
                <property type="bool" key="resizable">false</property>
                <property type="double" key="height">110</property>
                <property type="double" key="width">290</property>
                <property type="double" key="z">1</property>
                <property type="string" key="state">floating</property>
                <anchors target="3D View">
                    <line own="right" target="right" />
                    <line own="bottom" target="bottom" />
                </anchors>
            </ignition-gui>
            <sim_time>true</sim_time>
            <real_time>true</real_time>
            <real_time_factor>true</real_time_factor>
            <iterations>true</iterations>
            <topic>/world/SonglingEnvironment/stats</topic>
        </plugin>

        <plugin filename="EntityTree" name="Entity tree"></plugin>
    </gui>


    <model name="ground_plane">
      <static>true</static>
      <link name="link">
        <collision name="collision">
          <geometry>
            <!--plane>
              <normal>0 0 1</normal>
              <size>100 100</size>
            </plane-->
            <box>
              <size>20 20 0.1</size>
            </box>
          </geometry>
        </collision>
        <visual name="visual">
          <geometry>
            <!--plane>
              <normal>0 0 1</normal>
              <size>100 100</size>
            </plane-->
            <box>
              <size>20 20 0.1</size>
            </box>
          </geometry>
          <material>
            <ambient>0.8 0.8 0.8 1</ambient>
            <diffuse>0.8 0.8 0.8 1</diffuse>
            <specular>0.8 0.8 0.8 1</specular>
          </material>
        </visual>
      </link>
    </model>

    <light type="directional" name="sun">
        <cast_shadows>true</cast_shadows>
        <pose>0 0 10 0 0 0</pose>
        <diffuse>0.8 0.8 0.8 1</diffuse>
        <specular>0.2 0.2 0.2 1</specular>
        <attenuation>
            <range>1000</range>
            <constant>0.9</constant>
            <linear>0.01</linear>
            <quadrat>0.001</quadrat>
        </attenuation>
        <direction>-0.5 0.1 -0.9</direction>
    </light>

    <model name="limo">
        <link name="base_footprint">
            <inertial>
                <pose>0.007904637 0 0.14940820 0 0 0</pose>
                <mass>2.3657</mass>
                <inertial>
                    <ixx>0.240306</ixx>
                    <ixy>0</ixy>
                    <ixz>8.713350</ixz>
                    <iyy>0.961925</iyy>
                    <iyz>0</iyz>
                    <izz>0.961620</izz>
                </inertial>
            </inertial>
            <collision name="base_footprinnt_fixed_joint_lump__base_link_collision">
                <pose>0 0 0.15 0 0 0</pose>
                <geometry>
                    <box>
                        <size>0.13 0.12 0.1</size>
                    </box>
                </geometry>    
            </collision>
            <collision name="base_footprinnt_fixed_joint_lump__depth_camera_collision_collision1">
                <pose>0.084 0 0.18 0 0 0</pose>
                <geometry>
                    <box>
                        <size>0.02 0.06 0.015</size>
                    </box>
                </geometry>    
            </collision>
            <collision name="base_footprinnt_fixed_joint_lump__imu_collision_collision2">
                <pose>0 0 0.049999999 0 0 0</pose>
                <geometry>
                    <box>
                        <size>0.001 0.001 0.001</size>
                    </box>
                </geometry>    
            </collision>
            <collision name="base_footprinnt_fixed_joint_lump__laser_collision_collision3">
                <pose>0.103 0 0.116 0 0 0</pose>
                <geometry>
                    <cylinder>
                        <length>0.016</length>
                        <radius>0.032</radius>
                    </cylinder>
                </geometry>    
            </collision>
            <visual name="base_footprinnt_fixed_joint_lump__base_link_visual">
                <pose>0 0 0 0 0 1.57079</pose>
                <geometry>
                    <mesh>
                        <scale>1 1 1</scale>
                        <uri>meshes/limo_base.dae</uri>
                    </mesh>
                </geometry>
            </visual>
            <visual name="base_footprinnt_fixed_joint_lump__depth_camera_visual_visual1">
                <pose>0.084 0 0.18 0 0 0 </pose>
                <geometry>
                    <box>
                        <size>0.02 0.06 0.015</size>
                    </box>
                </geometry> 
                <material>
                    <diffuse>0 0 0 1</diffuse>
                    <ambient>0 0 0 1</ambient>
                </material> 
            </visual>
            <visual name="base_footprinnt_fixed_joint_lump__imu_visual_visual2">
                <pose>0 0 0.049999999 0 0 0 </pose>
                <geometry>
                    <box>
                        <size>0.001 0.001 0.001</size>
                    </box>
                </geometry> 
                <material>
                    <diffuse>0 0 0 1</diffuse>
                    <ambient>0 0 0 1</ambient>
                </material> 
            </visual>
            <visual name="base_footprinnt_fixed_joint_lump__laser_visual_visual3">
                <pose>0.103 0 0.116 0 0 0</pose>
                <geometry>
                    <cylinder>
                        <length>0.01</length>
                        <radius>0.02</radius>
                    </cylinder>
                </geometry> 
                <material>
                    <diffuse>0 0 0 1</diffuse>
                    <ambient>0 0 0 1</ambient>
                </material> 
            </visual>
            
            <sensor name="camera_front" type="rgbd_camera">
                <camera name="camera_front">
                    <horizontal_fov>1.3962634</horizontal_fov>
                    <lens>
                        <intrinsics>
                        <fx>26261.151116249</fx>
                        <fy>26261.151116249</fy>
                        <cx>320.5</cx>
                        <cy>240.5</cy>
                        <s>0</s>
                        </intrinsics>
                    </lens>
                    <distortion>
                        <k1>0.0</k1>
                        <k2>0.0</k2>
                        <k3>0.0</k3>
                        <p1>0.0</p1>
                        <p2>0.0</p2>
                        <center>0.5 0.5</center>
                    </distortion>
                    <image>
                        <width>640</width>
                        <height>480</height>
                        <format>R8G8B8</format>
                    </image>
                    <clip>
                        <near>0.02</near>
                        <far>300</far>
                    </clip>
                    <depth_camera>
                        <clip>
                            <near>0.1</near>
                            <far>10</far>
                        </clip>
                    </depth_camera>
                    <noise>
                        <type>gaussian</type>
                        <mean>0</mean>
                        <stddev>0.007</stddev>
                    </noise>
                </camera>
                <always_on>1</always_on>
                <update_rate>10</update_rate>
                <visualize>0</visualize>
                <topic>/limo/rgbd_camera</topic>
                <pose>0.084 0 0.18 0 -0 0</pose>
            </sensor>
            <gravity>true</gravity>
            <sensor name="imu_sensor" type="imu">
                <always_on>1</always_on>
                <update_rate>100</update_rate>
                <imu>
                    <enable_orientation>0</enable_orientation>
                    <angular_velocity>
                        <x>
                            <noise type="gaussian">
                                <mean>0</mean>
                                <stddev>0.009</stddev>
                                <bias_mean>0.00075</bias_mean>
                                <bias_stddev>0.005</bias_stddev>
                                <dynamic_bias_stddev>0.00002</dynamic_bias_stddev>
                                <dynamic_bias_correlation_time>400.0</dynamic_bias_correlation_time>
                                <precision>0.00025</precision>
                            </noise>
                        </x>
                        <y>
                            <noise type="gaussian">
                                <mean>0</mean>
                                <stddev>0.009</stddev>
                                <bias_mean>0.00075</bias_mean>
                                <bias_stddev>0.005</bias_stddev>
                                <dynamic_bias_stddev>0.00002</dynamic_bias_stddev>
                                <dynamic_bias_correlation_time>400.0</dynamic_bias_correlation_time>
                                <precision>0.00025</precision>
                            </noise>
                        </y>
                        <z>
                            <noise type="gaussian">
                                <mean>0</mean>
                                <stddev>0.009</stddev>
                                <bias_mean>0.00075</bias_mean>
                                <bias_stddev>0.005</bias_stddev>
                                <dynamic_bias_stddev>0.00002</dynamic_bias_stddev>
                                <dynamic_bias_correlation_time>400.0</dynamic_bias_correlation_time>
                                <precision>0.00025</precision>
                            </noise>
                        </z>
                    </angular_velocity>
                    <linear_acceleration>
                        <x>
                            <noise type="gaussian">
                                <mean>0</mean>
                                <stddev>0.021</stddev>
                                <bias_mean>0.05</bias_mean>
                                <bias_stddev>0.005</bias_stddev>
                                <dynamic_bias_stddev>0.000375</dynamic_bias_stddev>
                                <dynamic_bias_correlation_time>175.0</dynamic_bias_correlation_time>
                                <precision>0.005</precision>
                            </noise>
                        </x>
                        <y>
                            <noise type="gaussian">
                                <mean>0</mean>
                                <stddev>0.021</stddev>
                                <bias_mean>0.05</bias_mean>
                                <bias_stddev>0.005</bias_stddev>
                                <dynamic_bias_stddev>0.000375</dynamic_bias_stddev>
                                <dynamic_bias_correlation_time>175.0</dynamic_bias_correlation_time>
                                <precision>0.005</precision>
                            </noise>
                        </y>
                        <z>
                            <noise type="gaussian">
                                <mean>0</mean>
                                <stddev>0.021</stddev>
                                <bias_mean>0.05</bias_mean>
                                <bias_stddev>0.005</bias_stddev>
                                <dynamic_bias_stddev>0.000375</dynamic_bias_stddev>
                                <dynamic_bias_correlation_time>175.0</dynamic_bias_correlation_time>
                                <precision>0.005</precision>
                            </noise>
                        </z>
                    </linear_acceleration>
                </imu>
                <topic>/limo/imu</topic>
            </sensor>
            <!-- <sensor name="front_laser" type="lidar">
                <visualize>true</visualize>
                <alwaysOn>1</alwaysOn>
                <update_rate>8</update_rate>
                <lidar>
                    <scan>
                        <horizontal>
                            <samples>720</samples>
                            <resolution>1</resolution>
                            <min_angle>-1.396263</min_angle>
                            <max_angel>11.396263</max_angel>
                        </horizontal>
                        <vertical>
                            <samples>16</samples>
                            <resolution>1</resolution>
                            <min_angle>-0.261799</min_angle>
                            <max_angel>0.261799</max_angel>
                        </vertical>
                    </scan>
                    <rang>
                        <min>0.05</min>
                        <max>8.0</max>
                        <resolution>0.01</resolution>
                    </rang>
                    <noise>
                        <type>gaussian</type>
                        <mean>0</mean>
                        <stddev>0.01</stddev>
                    </noise>
                </lidar>
                <pose>0.103 0 0.116 0 -0 0</pose>
                <topic>limo/lidar</topic>
            </sensor> -->
        </link>

    <model name="limo_lidar">
        <pose>0.103 0 0.116 0 -0 0</pose>
        <link name="laser_link">
            <pose>0.103 0 0.116 0 -0 0</pose>
            <inertial>
            <mass>0.1</mass>
            <inertia>
                <ixx>0.000166667</ixx>
                <iyy>0.000166667</iyy>
                <izz>0.000166667</izz>
            </inertia>
            </inertial>
            <collision name="collision">
            <geometry>
                <box>
                <size>0.001 0.001 0.001</size>
                </box>
            </geometry>
            </collision>
            <visual name="visual">
            <geometry>
                <box>
                <size>0.001 0.001 0.001</size>
                </box>
            </geometry>
            </visual>

            <sensor name='gpu_lidar' type='gpu_lidar'>
            <topic>lidar</topic>
            <update_rate>10</update_rate>
            <lidar>
                <scan>
                <horizontal>
                    <samples>640</samples>
                    <resolution>1</resolution>
                    <min_angle>-1.396263</min_angle>
                    <max_angle>1.396263</max_angle>
                </horizontal>
                <vertical>
                    <samples>16</samples>
                    <resolution>1</resolution>
                    <min_angle>-0.261799</min_angle>
                    <max_angle>0.261799</max_angle>
                </vertical>
                </scan>
                <range>
                <min>0.08</min>
                <max>10.0</max>
                <resolution>0.01</resolution>
                </range>
            </lidar>
            <alwaysOn>1</alwaysOn>
            <visualize>true</visualize>
            </sensor>

    <!-- <sensor name="gpu_lidar" type="gpu_lidar">
                <visualize>true</visualize>
                <alwaysOn>1</alwaysOn>
                <update_rate>8</update_rate>
                <lidar>
                    <scan>
                        <horizontal>
                            <samples>720</samples>
                            <resolution>1</resolution>
                            <min_angle>-1.396263</min_angle>
                            <max_angel>11.396263</max_angel>
                        </horizontal>
                        <vertical>
                            <samples>16</samples>
                            <resolution>1</resolution>
                            <min_angle>-0.261799</min_angle>
                            <max_angel>0.261799</max_angel>
                        </vertical>
                    </scan>
                    <rang>
                        <min>0.05</min>
                        <max>8.0</max>
                        <resolution>0.01</resolution>
                    </rang>
                    <noise>
                        <type>gaussian</type>
                        <mean>0</mean>
                        <stddev>0.01</stddev>
                    </noise>
                </lidar>
                <pose>0.103 0 0.116 0 -0 0</pose>
                <topic>limo/lidar</topic>
            </sensor>  -->

      </link>
    </model>
        <joint name="left_steering_hinge_wheel" type="revolute">
            <pose relative_to="base_footprint">0.1 0.07 0.049002 0 0 0</pose>
            <parent>base_footprint</parent>
            <child>left_steering_hinge</child>
            <axis>
                <xyz>0 0 1</xyz>
                <limit>
                    <lower>-0.523598767</lower>
                    <upper>0.523598767</upper>
                    <effort>5</effort>
                    <velocity>0.5</velocity>
                </limit>
                <dynamics>
                    <damping>1</damping>
                    <friction>2</friction>
                    <spring_reference>0</spring_reference>
                    <spring_stiffness>0</spring_stiffness>
                </dynamics>
            </axis>
        </joint>
        <link name="left_steering_hinge">
            <pose relative_to="left_steering_hinge_wheel">0 0 0 0 0 0</pose>
            <inertial>
                <pose>0 0 0 0 0 0</pose>
                <mass>0.25</mass>                
                <inertia>
                    <ixx>0.00525</ixx>
                    <ixy>0</ixy>
                    <ixz>0</ixz>
                    <iyy>0.00035</iyy>
                    <iyz>0</iyz>
                    <izz>0.00525</izz>
                </inertia>
            </inertial>
            <collision name="left_steering_hinge_collision">
                <pose>0 0.0225 0 1.57079632 0 0</pose>
                <geometry>
                    <cylinder>
                        <radius>0.035</radius>
                        <length>0.045</length>
                    </cylinder>
                </geometry>
            </collision>
            <visual name="left_steering_hinge_visual">
                <pose>0 0 0 0 0 0</pose>
                <geometry>
                    <cylinder>
                        <radius>0.0001</radius>
                        <length>0.0001</length>
                    </cylinder>
                </geometry>
            </visual>
        </link>
        <joint name="front_left_wheel" type="revolute">
            <pose relative_to="left_steering_hinge">0 0 0 0 0 0</pose>
            <parent>left_steering_hinge</parent>
            <child>front_left_wheel_link</child>
            <axis>
                <xyz>0 1 0</xyz>
                <limit>
                    <lower>-1e16</lower>
                    <upper>1e16</upper>
                </limit>
                <dynamics>
                    <damping>1</damping>
                    <friction>2</friction>
                    <spring_reference>0</spring_reference>
                    <spring_stiffness>0</spring_stiffness>
                </dynamics>
            </axis>
        </joint>
        <link name="front_left_wheel_link">
            <pose relative_to="front_left_wheel">0 0 0 0 0 0</pose>
            <inertial>
                <pose>0 0 0 0 0 0</pose>
                <mass>0.25</mass>                
                <inertia>
                    <ixx>0.00525</ixx>
                    <ixy>0</ixy>
                    <ixz>0</ixz>
                    <iyy>0.00035</iyy>
                    <iyz>0</iyz>
                    <izz>0.00525</izz>
                </inertia>
            </inertial>
            <collision name="front_left_wheel_link_collision">
                <pose>0 0.0225 0 1.57079632 0 0</pose>
                <geometry>
                    <cylinder>
                        <radius>0.045</radius>
                        <length>0.045</length>
                    </cylinder>
                </geometry>
            </collision>
            <visual name="front_left_wheel_link_visual">
                <pose>0 0 0 0 0 0</pose>
                <geometry>
                    <mesh>
                        <scale>1 1 1</scale>
                        <uri>meshes/limo_wheel.dae</uri>
                    </mesh>
                </geometry>
            </visual>
        </link>
        <joint name="rear_left_wheel" type="revolute">
            <pose relative_to="base_footprint">-0.1 0.07 0.05 0 0 0</pose>
            <parent>base_footprint</parent>
            <child>rear_left_wheel_link</child>
            <axis>
                <xyz>0 1 0</xyz>
                <limit>
                    <lower>-1e16</lower>
                    <upper>1e16</upper>
                </limit>
                <dynamics>
                    <spring_reference>0</spring_reference>
                    <spring_stiffness>0</spring_stiffness>
                </dynamics>
            </axis>
        </joint>
        <link name="rear_left_wheel_link">
            <pose relative_to="rear_left_wheel">0 0 0 0 0 0</pose>
            <inertial>
                <pose>0 0 0 0 0 0</pose>
                <mass>0.5</mass>                
                <inertia>
                    <ixx>0.01055</ixx>
                    <ixy>0</ixy>
                    <ixz>0</ixz>
                    <iyy>0.00075</iyy>
                    <iyz>0</iyz>
                    <izz>0.01055</izz>
                </inertia>
            </inertial>
            <collision name="rear_left_wheel_link_collision">
                <pose>0 0.0225 0 1.57079632 0 0</pose>
                <geometry>
                    <cylinder>
                        <radius>0.045</radius>
                        <length>0.045</length>
                    </cylinder>
                </geometry>
            </collision>
            <visual name="rear_left_wheel_link_visual">
                <pose>0 0 0 0 0 0</pose>
                <geometry>
                    <mesh>
                        <scale>1 1 1</scale>
                        <uri>meshes/limo_wheel.dae</uri>
                    </mesh>
                </geometry>
            </visual>
        </link>
        <joint name="rear_right_wheel" type="revolute">
            <pose relative_to="base_footprint">-0.1 -0.07 0.05 3.1415926 0 0</pose>
            <parent>base_footprint</parent>
            <child>rear_right_wheel_link</child>
            <axis>
                <xyz>0 -1 0</xyz>
                <limit>
                    <lower>-1e16</lower>
                    <upper>1e16</upper>
                </limit>
                <dynamics>
                    <spring_reference>0</spring_reference>
                    <spring_stiffness>0</spring_stiffness>
                </dynamics>
            </axis>
        </joint>
        <link name="rear_right_wheel_link">
            <pose relative_to="rear_right_wheel">0 0 0 0 0 0</pose>
            <inertial>
                <pose>0 0 0 0 0 0</pose>
                <mass>0.5</mass>                
                <inertia>
                    <ixx>0.01055</ixx>
                    <ixy>0</ixy>
                    <ixz>0</ixz>
                    <iyy>0.00075</iyy>
                    <iyz>0</iyz>
                    <izz>0.01055</izz>
                </inertia>
            </inertial>
            <collision name="rear_right_wheel_link_collision">
                <pose>0 0.0225 0 1.57079632 0 0</pose>
                <geometry>
                    <cylinder>
                        <radius>0.045</radius>
                        <length>0.045</length>
                    </cylinder>
                </geometry> 
            </collision>
            <visual name="rear_right_wheel_link_visual">
                <pose>0 0 0 0 0 0</pose>
                <geometry>
                    <mesh>
                        <scale>1 1 1</scale>
                        <uri>meshes/limo_wheel.dae</uri>
                    </mesh>
                </geometry>
            </visual>
        </link>
        <joint name="right_steering_hinge_wheel" type="revolute">
            <pose relative_to="base_footprint">0.1 -0.07 0.05 3.1415926 0 0</pose>
            <parent>base_footprint</parent>
            <child>right_steering_hinge</child>
            <axis>
                <xyz>0 0 -1</xyz>
                <limit>
                    <lower>-0.523598767</lower>
                    <upper>0.523598767</upper>
                    <effort>5</effort>
                    <velocity>0.5</velocity>
                </limit>
                <dynamics>
                    <damping>1</damping>
                    <friction>2</friction>
                    <spring_reference>0</spring_reference>
                    <spring_stiffness>0</spring_stiffness>
                </dynamics>
            </axis>
        </joint>
        <link name="right_steering_hinge">
            <pose relative_to="right_steering_hinge_wheel">0 0 0 0 0 0</pose>
            <inertial>
                <pose>0 0 0 0 0 0</pose>
                <mass>0.25</mass>                
                <inertia>
                    <ixx>0.00525</ixx>
                    <ixy>0</ixy>
                    <ixz>0</ixz>
                    <iyy>0.00035</iyy>
                    <iyz>0</iyz>
                    <izz>0.00525</izz>
                </inertia>
            </inertial>
            <collision name="right_steering_hinge_collision">
                <pose>0 0.0225 0 1.57079632 0 0</pose>
                <geometry>
                    <cylinder>
                        <length>0.045</length>
                        <radius>0.035</radius>
                    </cylinder>
                </geometry>
            </collision>
            <visual name="right_steering_hinge_visual">
                <pose>0 0 0 0 0 0</pose>
                <geometry>
                    <cylinder>
                        <length>0.0001</length>
                        <radius>0.0001</radius>
                    </cylinder>
                </geometry>
            </visual>
        </link>
        <joint name="front_right_wheel" type="revolute">
            <pose relative_to="right_steering_hinge">0 0 0 0 0 0</pose>
            <parent>right_steering_hinge</parent>
            <child>front_right_wheel_link</child>
            <axis>
                <xyz>0 -1 0</xyz>
                <limit>
                    <lower>-1e16</lower>
                    <upper>1e16</upper>
                </limit>
                <dynamics>
                    <spring_reference>0</spring_reference>
                    <spring_stiffness>0</spring_stiffness>
                </dynamics>
            </axis>
        </joint>
        <link name="front_right_wheel_link">
            <pose relative_to="front_right_wheel">0 0 0 0 0 0</pose>
            <inertial>
                <pose>0 0 0 0 0 0</pose>
                <mass>0.25</mass>                
                <inertia>
                    <ixx>0.00525</ixx>
                    <ixy>0</ixy>
                    <ixz>0</ixz>
                    <iyy>0.00035</iyy>
                    <iyz>0</iyz>
                    <izz>0.00525</izz>
                </inertia>
            </inertial>
            <collision name="front_right_wheel_link_collision">
                <pose>0 0.0225 0 1.57079632 0 0</pose>
                <geometry>
                    <cylinder>
                        <radius>0.045</radius>
                        <length>0.045</length>
                    </cylinder>
                </geometry>
            </collision>
            <visual name="front_right_wheel_link_visual">
                <pose>0 0 0 0 0 0</pose>
                <geometry>
                    <mesh>
                        <scale>1 1 1</scale>
                        <uri>meshes/limo_wheel.dae</uri>
                    </mesh>
                </geometry>
            </visual>
        </link>
        <static>false</static>

        <plugin filename="ignition-gazebo-ackermann-steering-system" name="ignition::gazebo::systems::AckermannSteering">
            <left_joint>front_left_wheel</left_joint>
            <left_joint>rear_left_wheel</left_joint>
            <right_joint>front_right_wheel</right_joint>
            <right_joint>rear_right_wheel</right_joint>
            <left_steering_joint>left_steering_hinge_wheel</left_steering_joint>
            <right_steering_joint>right_steering_hinge_wheel</right_steering_joint>
            <wheel_separation>0.172</wheel_separation>
            <wheel_radius>0.045</wheel_radius>
            <min_velocity>-1</min_velocity>
            <max_velocity>1</max_velocity>
            <min_acceleration>-3</min_acceleration>
            <max_acceleration>3</max_acceleration>
            <topic>limo/cmd_vel</topic>
        </plugin>
        <plugin filename="libignition-gazebo-pose-publisher-system.so" name="ignition::gazebo::systems::PosePublisher">
            <publish_link_pose>true</publish_link_pose>
            <publish_sensor_pose>true</publish_sensor_pose>
            <publish_collision_pose>false</publish_collision_pose>
            <publish_visual_pose>false</publish_visual_pose>
            <publish_nested_model_pose>false</publish_nested_model_pose>
            <use_pose_vector_msg>true</use_pose_vector_msg>
            <static_publisher>true</static_publisher>
            <static_update_frequency>1</static_update_frequency>
        </plugin>
        <plugin filename="ignition-gazebo-joint-state-publisher-system" name="ignition::gazebo::systems::JointStatePublisher">
            <topic>limo/joint_states</topic>
        </plugin>
    </model>
    </world>
</sdf>
